<?xml version="1.0"?>
<robot xmlns:xacro="http://www.ros.org/wiki/xacro" name="iai_donbot">

  <xacro:include filename="$(find iai_donbot_description)/robots/iai_donbot.xacro"/>

  <!-- <link name="map"/> -->

  <iai_donbot/>

  <joint name="refills_tool_frame_joint" type="fixed">
    <parent link="gripper_tool_frame"/>
    <child link="refills_tool_frame"/>
    <origin xyz="0 0 0.037" rpy="0.0 0.0 0.0" />
  </joint>

  <link name="refills_tool_frame"/>

  <joint name="refills_finger_joint" type="continuous">
    <parent link="refills_tool_frame"/>
    <child link="refills_finger"/>
    <axis xyz="1 0 0"/>
  </joint>

  <link name="refills_finger"/>

</robot>
