<robot
  name="UR3_4">
  <link
    name="base_link">
    <inertial>
      <origin
        xyz="-9.17917664867731E-05 0.00176225993189883 0.0221985040155013"
        rpy="0 0 0" />
      <mass
        value="0.615785178708615" />
      <inertia
        ixx="0.000798391609217155"
        ixy="-2.36939317248351E-06"
        ixz="2.31945715838129E-06"
        iyy="0.000785313593008411"
        iyz="-2.95609579480635E-05"
        izz="0.00102988796085097" />
    </inertial>
    <visual>
      <origin
        xyz="0 0 0"
        rpy="0 0 0" />
      <geometry>
        <mesh
          filename="package://UR3_4/meshes/base_link.STL" />
      </geometry>
      <material
        name="">
        <color
          rgba="0.792156862745098 0.819607843137255 0.933333333333333 1" />
      </material>
    </visual>
    <collision>
      <origin
        xyz="0 0 0"
        rpy="0 0 0" />
      <geometry>
        <mesh
          filename="package://UR3_4/meshes/base_link.STL" />
      </geometry>
    </collision>
  </link>
  <link
    name="link1">
    <inertial>
      <origin
        xyz="-1.16579425962352E-05 0.0542331848711327 0.00709561655792605"
        rpy="0 0 0" />
      <mass
        value="0.752018184613331" />
      <inertia
        ixx="0.00119772991115785"
        ixy="-1.57544981962304E-07"
        ixz="-1.40423013378356E-07"
        iyy="0.000903952766448813"
        iyz="9.95161463495687E-05"
        izz="0.00111931029014456" />
    </inertial>
    <visual>
      <origin
        xyz="0 0 0"
        rpy="0 0 0" />
      <geometry>
        <mesh
          filename="package://UR3_4/meshes/link1.STL" />
      </geometry>
      <material
        name="">
        <color
          rgba="0.792156862745098 0.819607843137255 0.933333333333333 1" />
      </material>
    </visual>
    <collision>
      <origin
        xyz="0 0 0"
        rpy="0 0 0" />
      <geometry>
        <mesh
          filename="package://UR3_4/meshes/link1.STL" />
      </geometry>
    </collision>
  </link>
  <joint
    name="jnt1"
    type="revolute">
    <origin
      xyz="0 0.0026751 0.062026"
      rpy="1.6139 -0.00078894 -3.1233" />
    <parent
      link="base_link" />
    <child
      link="link1" />
    <axis
      xyz="-0.00078894 -0.99907 0.043081" />
    <limit
      lower="0"
      upper="6.2"
      effort="0"
      velocity="0" />
  </joint>
  <link
    name="link2">
    <inertial>
      <origin
        xyz="-1.15992943500445E-05 0.0539289003732488 0.00709568345258235"
        rpy="0 0 0" />
      <mass
        value="0.752020006182499" />
      <inertia
        ixx="0.00119773082119344"
        ixy="-1.570312570916E-07"
        ixz="-1.39555784495906E-07"
        iyy="0.00090395542701678"
        iyz="9.95171516793994E-05"
        izz="0.0011193119653482" />
    </inertial>
    <visual>
      <origin
        xyz="0 0 0"
        rpy="0 0 0" />
      <geometry>
        <mesh
          filename="package://UR3_4/meshes/link2.STL" />
      </geometry>
      <material
        name="">
        <color
          rgba="0.792156862745098 0.819607843137255 0.933333333333333 1" />
      </material>
    </visual>
    <collision>
      <origin
        xyz="0 0 0"
        rpy="0 0 0" />
      <geometry>
        <mesh
          filename="package://UR3_4/meshes/link2.STL" />
      </geometry>
    </collision>
  </link>
  <joint
    name="jnt2"
    type="revolute">
    <origin
      xyz="0.00015682 0.065852 0.054304"
      rpy="1.5708 -9.0206E-17 3.1409" />
    <parent
      link="link1" />
    <child
      link="link2" />
    <axis
      xyz="0 -1 0" />
    <limit
      lower="0"
      upper="6.2"
      effort="0"
      velocity="0" />
  </joint>
  <link
    name="link3">
    <inertial>
      <origin
        xyz="2.98842200985305E-11 -1.58985949405555E-10 0.0695674237635138"
        rpy="0 0 0" />
      <mass
        value="0.552737646055454" />
      <inertia
        ixx="0.00126229583610101"
        ixy="1.27200881717884E-10"
        ixz="-3.86920646792959E-14"
        iyy="0.00126229828794338"
        iyz="-2.42310164634319E-12"
        izz="0.000345387859679815" />
    </inertial>
    <visual>
      <origin
        xyz="0 0 0"
        rpy="0 0 0" />
      <geometry>
        <mesh
          filename="package://UR3_4/meshes/link3.STL" />
      </geometry>
      <material
        name="">
        <color
          rgba="0.792156862745098 0.819607843137255 0.933333333333333 1" />
      </material>
    </visual>
    <collision>
      <origin
        xyz="0 0 0"
        rpy="0 0 0" />
      <geometry>
        <mesh
          filename="package://UR3_4/meshes/link3.STL" />
      </geometry>
    </collision>
  </link>
  <joint
    name="jnt3"
    type="revolute">
    <origin
      xyz="0.00015682 0.065548 0.05176"
      rpy="-1.9475E-16 -1.0122E-15 1.1551" />
    <parent
      link="link2" />
    <child
      link="link3" />
    <axis
      xyz="0 0 1" />
    <limit
      lower="0"
      upper="6.2"
      effort="0"
      velocity="0" />
  </joint>
  <link
    name="link4">
    <inertial>
      <origin
        xyz="-0.0373245831851897 -0.00757317719745282 1.5181359549199E-06"
        rpy="0 0 0" />
      <mass
        value="0.339212926694728" />
      <inertia
        ixx="0.000256473335771864"
        ixy="3.65273939584755E-05"
        ixz="3.07905866015282E-09"
        iyy="0.000286981954081314"
        iyz="-2.11118846806774E-09"
        izz="0.000282798048740792" />
    </inertial>
    <visual>
      <origin
        xyz="0 0 0"
        rpy="0 0 0" />
      <geometry>
        <mesh
          filename="package://UR3_4/meshes/link4.STL" />
      </geometry>
      <material
        name="">
        <color
          rgba="0.792156862745098 0.819607843137255 0.933333333333333 1" />
      </material>
    </visual>
    <collision>
      <origin
        xyz="0 0 0"
        rpy="0 0 0" />
      <geometry>
        <mesh
          filename="package://UR3_4/meshes/link4.STL" />
      </geometry>
    </collision>
  </link>
  <joint
    name="jnt4"
    type="revolute">
    <origin
      xyz="0 0 0.14633"
      rpy="1.7932 1.5708 2.1973" />
    <parent
      link="link3" />
    <child
      link="link4" />
    <axis
      xyz="-1 0 0" />
    <limit
      lower="0"
      upper="6.2"
      effort="0"
      velocity="0" />
  </joint>
  <link
    name="link5">
    <inertial>
      <origin
        xyz="0.0550451072198847 0.0123769577291497 4.65258919168932E-08"
        rpy="0 0 0" />
      <mass
        value="0.315980001610279" />
      <inertia
        ixx="0.000256415626401478"
        ixy="6.62359487957181E-05"
        ixz="1.04055969425121E-09"
        iyy="0.00022631890140513"
        iyz="1.43323591695389E-09"
        izz="0.000291465583650888" />
    </inertial>
    <visual>
      <origin
        xyz="0 0 0"
        rpy="0 0 0" />
      <geometry>
        <mesh
          filename="package://UR3_4/meshes/link5.STL" />
      </geometry>
      <material
        name="">
        <color
          rgba="0.792156862745098 0.819607843137255 0.933333333333333 1" />
      </material>
    </visual>
    <collision>
      <origin
        xyz="0 0 0"
        rpy="0 0 0" />
      <geometry>
        <mesh
          filename="package://UR3_4/meshes/link5.STL" />
      </geometry>
    </collision>
  </link>
  <joint
    name="jnt5"
    type="revolute">
    <origin
      xyz="-0.045564 -0.021967 0"
      rpy="-1.5788 5.8981E-16 -1.5708" />
    <parent
      link="link4" />
    <child
      link="link5" />
    <axis
      xyz="1 0 0" />
    <limit
      lower="0"
      upper="6.2"
      effort="0"
      velocity="0" />
  </joint>
  <link
    name="link6">
    <inertial>
      <origin
        xyz="-1.02355826592238E-09 -5.35945843260777E-10 -0.0652977977164337"
        rpy="0 0 0" />
      <mass
        value="0.321040378507981" />
      <inertia
        ixx="0.000570290480838894"
        ixy="-9.41403448453932E-10"
        ixz="-1.0366737266069E-11"
        iyy="0.000570295519173622"
        iyz="-5.53985581887803E-12"
        izz="0.000126061026996997" />
    </inertial>
    <visual>
      <origin
        xyz="0 0 0"
        rpy="0 0 0" />
      <geometry>
        <mesh
          filename="package://UR3_4/meshes/link6.STL" />
      </geometry>
      <material
        name="">
        <color
          rgba="0.792156862745098 0.819607843137255 0.933333333333333 1" />
      </material>
    </visual>
    <collision>
      <origin
        xyz="0 0 0"
        rpy="0 0 0" />
      <geometry>
        <mesh
          filename="package://UR3_4/meshes/link6.STL" />
      </geometry>
    </collision>
  </link>
  <joint
    name="jnt6"
    type="revolute">
    <origin
      xyz="0.071244 0.046024 0"
      rpy="-1.5708 -0.12492 3.1416" />
    <parent
      link="link5" />
    <child
      link="link6" />
    <axis
      xyz="0 0 -1" />
    <limit
      lower="0"
      upper="6.2"
      effort="0"
      velocity="0" />
  </joint>
  <link
    name="link7">
    <inertial>
      <origin
        xyz="-0.0367074220900242 -0.00553144984424089 4.13709880187074E-07"
        rpy="0 0 0" />
      <mass
        value="0.276073153901797" />
      <inertia
        ixx="0.000181700922840963"
        ixy="1.688946906456E-05"
        ixz="2.07092873180666E-09"
        iyy="0.000178933890243897"
        iyz="-3.75045458637156E-09"
        izz="0.000215939814591068" />
    </inertial>
    <visual>
      <origin
        xyz="0 0 0"
        rpy="0 0 0" />
      <geometry>
        <mesh
          filename="package://UR3_4/meshes/link7.STL" />
      </geometry>
      <material
        name="">
        <color
          rgba="0.792156862745098 0.819607843137255 0.933333333333333 1" />
      </material>
    </visual>
    <collision>
      <origin
        xyz="0 0 0"
        rpy="0 0 0" />
      <geometry>
        <mesh
          filename="package://UR3_4/meshes/link7.STL" />
      </geometry>
    </collision>
  </link>
  <joint
    name="jnt7"
    type="revolute">
    <origin
      xyz="0 0 -0.12281"
      rpy="-1.6061 -1.5708 -2.9597" />
    <parent
      link="link6" />
    <child
      link="link7" />
    <axis
      xyz="-1 0 0" />
    <limit
      lower="0"
      upper="6.2"
      effort="0"
      velocity="0" />
  </joint>
  <link
    name="link8">
    <inertial>
      <origin
        xyz="-0.042305424857576 -0.00553162235503007 4.50191684514545E-07"
        rpy="0 0 0" />
      <mass
        value="0.276071483529249" />
      <inertia
        ixx="0.000181699601817208"
        ixy="1.68885039442407E-05"
        ixz="2.23924759841302E-09"
        iyy="0.000178941863186415"
        iyz="-3.42151886666245E-09"
        izz="0.000215946484205604" />
    </inertial>
    <visual>
      <origin
        xyz="0 0 0"
        rpy="0 0 0" />
      <geometry>
        <mesh
          filename="package://UR3_4/meshes/link8.STL" />
      </geometry>
      <material
        name="">
        <color
          rgba="0.792156862745098 0.819607843137255 0.933333333333333 1" />
      </material>
    </visual>
    <collision>
      <origin
        xyz="0 0 0"
        rpy="0 0 0" />
      <geometry>
        <mesh
          filename="package://UR3_4/meshes/link8.STL" />
      </geometry>
    </collision>
  </link>
  <joint
    name="jnt8"
    type="revolute">
    <origin
      xyz="-0.044162 -0.03364 0"
      rpy="1.5706 -4.0049E-15 1.5708" />
    <parent
      link="link7" />
    <child
      link="link8" />
    <axis
      xyz="1 0 0" />
    <limit
      lower="0"
      upper="6.2"
      effort="0"
      velocity="0" />
  </joint>
  <link
    name="link9">
    <inertial>
      <origin
        xyz="-0.0375715626595217 -0.00553145550412851 4.12898463817216E-07"
        rpy="0 0 0" />
      <mass
        value="0.276072926967329" />
      <inertia
        ixx="0.000181700720449304"
        ixy="1.68894771258753E-05"
        ixz="2.09064022016729E-09"
        iyy="0.000178933701503148"
        iyz="-3.73625822853678E-09"
        izz="0.000215939730131613" />
    </inertial>
    <visual>
      <origin
        xyz="0 0 0"
        rpy="0 0 0" />
      <geometry>
        <mesh
          filename="package://UR3_4/meshes/link9.STL" />
      </geometry>
      <material
        name="">
        <color
          rgba="0.792156862745098 0.819607843137255 0.933333333333333 1" />
      </material>
    </visual>
    <collision>
      <origin
        xyz="0 0 0"
        rpy="0 0 0" />
      <geometry>
        <mesh
          filename="package://UR3_4/meshes/link9.STL" />
      </geometry>
    </collision>
  </link>
  <joint
    name="jnt9"
    type="revolute">
    <origin
      xyz="-0.04976 -0.038374 0"
      rpy="1.5383 -7.4333E-16 1.5708" />
    <parent
      link="link8" />
    <child
      link="link9" />
    <axis
      xyz="-1 0 0" />
    <limit
      lower="0"
      upper="6.2"
      effort="0"
      velocity="0" />
  </joint>
  <link
    name="link10">
    <inertial>
      <origin
        xyz="-3.4161258023746E-11 0.000103305758782479 -0.019297780219535"
        rpy="0 0 0" />
      <mass
        value="0.115355247294107" />
      <inertia
        ixx="4.32035974145055E-05"
        ixy="-5.73656517550076E-13"
        ixz="1.20229456345579E-12"
        iyy="4.34162195885928E-05"
        iyz="-1.08131291624742E-07"
        izz="5.90666750281698E-05" />
    </inertial>
    <visual>
      <origin
        xyz="0 0 0"
        rpy="0 0 0" />
      <geometry>
        <mesh
          filename="package://UR3_4/meshes/link10.STL" />
      </geometry>
      <material
        name="">
        <color
          rgba="0.792156862745098 0.819607843137255 0.933333333333333 1" />
      </material>
    </visual>
    <collision>
      <origin
        xyz="0 0 0"
        rpy="0 0 0" />
      <geometry>
        <mesh
          filename="package://UR3_4/meshes/link10.STL" />
      </geometry>
    </collision>
  </link>
  <joint
    name="jnt10"
    type="revolute">
    <origin
      xyz="-0.045026 -0.042675 0"
      rpy="-1.5708 -1.5653 3.1027E-13" />
    <parent
      link="link9" />
    <child
      link="link10" />
    <axis
      xyz="0 0 1" />
    <limit
      lower="0"
      upper="6.2"
      effort="0"
      velocity="0" />
  </joint>
</robot>